[ERROR 2020-12-13 06:36:29,632] function_runner.py: 254  Runner Thread raised error.
Traceback (most recent call last):
  File "/home/zack/github/595_EECS_final_project/csqa/venv/lib/python3.8/site-packages/ray/tune/function_runner.py", line 248, in run
    self._entrypoint()
  File "/home/zack/github/595_EECS_final_project/csqa/venv/lib/python3.8/site-packages/ray/tune/function_runner.py", line 315, in entrypoint
    return self._trainable_func(self.config, self._status_reporter,
  File "/home/zack/github/595_EECS_final_project/csqa/venv/lib/python3.8/site-packages/ray/tune/function_runner.py", line 575, in _trainable_func
    output = fn()
  File "/home/zack/github/595_EECS_final_project/csqa/pytorch_reimpl.py", line 176, in train_tune
    model = Model(config)
  File "/home/zack/github/595_EECS_final_project/csqa/pytorch_reimpl.py", line 68, in __init__
    self.x_train, self.y_train = preprocess(training_data, tokenizer, self.model_config["max_seq_length"],
  File "/home/zack/github/595_EECS_final_project/csqa/pytorch_reimpl.py", line 34, in preprocess
    x = {k: v.view(-1, NUM_CHOICES, config["max_seq_length"])[:end] for k, v in x.items()}
  File "/home/zack/github/595_EECS_final_project/csqa/pytorch_reimpl.py", line 34, in <dictcomp>
    x = {k: v.view(-1, NUM_CHOICES, config["max_seq_length"])[:end] for k, v in x.items()}
RuntimeError: shape '[-1, 5, 32]' is invalid for input of size 2049840
Exception in thread Thread-2:
Traceback (most recent call last):
  File "/usr/lib/python3.8/threading.py", line 932, in _bootstrap_inner
    self.run()
  File "/home/zack/github/595_EECS_final_project/csqa/venv/lib/python3.8/site-packages/ray/tune/function_runner.py", line 267, in run
    raise e
  File "/home/zack/github/595_EECS_final_project/csqa/venv/lib/python3.8/site-packages/ray/tune/function_runner.py", line 248, in run
    self._entrypoint()
  File "/home/zack/github/595_EECS_final_project/csqa/venv/lib/python3.8/site-packages/ray/tune/function_runner.py", line 315, in entrypoint
    return self._trainable_func(self.config, self._status_reporter,
  File "/home/zack/github/595_EECS_final_project/csqa/venv/lib/python3.8/site-packages/ray/tune/function_runner.py", line 575, in _trainable_func
    output = fn()
  File "/home/zack/github/595_EECS_final_project/csqa/pytorch_reimpl.py", line 176, in train_tune
    model = Model(config)
  File "/home/zack/github/595_EECS_final_project/csqa/pytorch_reimpl.py", line 68, in __init__
    self.x_train, self.y_train = preprocess(training_data, tokenizer, self.model_config["max_seq_length"],
  File "/home/zack/github/595_EECS_final_project/csqa/pytorch_reimpl.py", line 34, in preprocess
    x = {k: v.view(-1, NUM_CHOICES, config["max_seq_length"])[:end] for k, v in x.items()}
  File "/home/zack/github/595_EECS_final_project/csqa/pytorch_reimpl.py", line 34, in <dictcomp>
    x = {k: v.view(-1, NUM_CHOICES, config["max_seq_length"])[:end] for k, v in x.items()}
RuntimeError: shape '[-1, 5, 32]' is invalid for input of size 2049840
